#VRML_SIM R2023b utf8

EXTERNPROTO "https://raw.githubusercontent.com/cyberbotics/webots/R2023b/projects/objects/backgrounds/protos/TexturedBackground.proto"
EXTERNPROTO "https://raw.githubusercontent.com/cyberbotics/webots/R2023b/projects/objects/backgrounds/protos/TexturedBackgroundLight.proto"
EXTERNPROTO "https://raw.githubusercontent.com/cyberbotics/webots/R2023b/projects/objects/floors/protos/RectangleArena.proto"

WorldInfo {
}
Viewpoint {
  orientation -0.2590822126252526 0.6730554750274391 0.6927284710741947 1.014396014206927
  position -0.8545868821100358 -0.773793179312005 0.5499896571500924
}
TexturedBackground {
}
TexturedBackgroundLight {
}
RectangleArena {
  floorSize 2 2
  floorAppearance PBRAppearance {
    roughness 1
    roughnessMap ImageTexture {
      url [
        "https://raw.githubusercontent.com/cyberbotics/webots/R2023b/projects/appearances/protos/textures/parquetry/mosaic_parquetry_roughness.jpg"
      ]
    }
    metalness 0
    normalMap ImageTexture {
      url [
        "https://raw.githubusercontent.com/cyberbotics/webots/R2023b/projects/appearances/protos/textures/parquetry/mosaic_parquetry_normal.jpg"
      ]
    }
    occlusionMap ImageTexture {
      url [
        "https://raw.githubusercontent.com/cyberbotics/webots/R2023b/projects/appearances/protos/textures/parquetry/mosaic_parquetry_occlusion.jpg"
      ]
    }
  }
}
Solid {
  translation 0.45 -0.73 0.05
  rotation 0 0 -1 -0.13090030610042527
  children [
    DEF obstacle1 Shape {
      appearance PBRAppearance {
        baseColor 0 0 0
        roughness 1
        metalness 0
      }
      geometry Box {
        size 0.1 0.1 0.1
      }
    }
  ]
  boundingObject USE obstacle1
  locked TRUE
}
Solid {
  translation 0.666748 -0.198009 0.05
  rotation 0 0 -1 -1.3089953071795861
  children [
    DEF obstacle2 Shape {
      appearance PBRAppearance {
        baseColor 0 0 0
        roughness 1
        metalness 0
      }
      geometry Box {
        size 0.2 0.1 0.1
      }
    }
  ]
  name "solid(1)"
  boundingObject USE obstacle2
  locked TRUE
}
Solid {
  translation 0.36358 0.381911 0.05
  rotation 0 0 -1 -1.047195307179586
  children [
    DEF obstacle3 Shape {
      appearance PBRAppearance {
        baseColor 0 0 0
        roughness 1
        metalness 0
      }
      geometry Box {
        size 0.12 0.1 0.1
      }
    }
  ]
  name "solid(3)"
  boundingObject USE obstacle3
  locked TRUE
}
Solid {
  translation -0.380764 0.661551 0.05
  rotation 0 0 1 2.09439
  children [
    DEF obstacle4 Shape {
      appearance PBRAppearance {
        baseColor 0 0 0
        roughness 1
        metalness 0
      }
      geometry Box {
        size 0.12 0.1 0.1
      }
    }
  ]
  name "solid(4)"
  boundingObject USE obstacle4
  locked TRUE
}
Solid {
  translation -0.545793 -0.0756207 0.05
  rotation 0 0 1 1.83259
  children [
    DEF obstacle5 Shape {
      appearance PBRAppearance {
        baseColor 0 0 0
        roughness 1
        metalness 0
      }
      geometry Box {
        size 0.1 0.3 0.1
      }
    }
  ]
  name "solid(5)"
  boundingObject USE obstacle5
  locked TRUE
}
Solid {
  translation -0.356546 -0.527723 0
  rotation 0 0 1 2.8797896938995744
  children [
    Shape {
      appearance PBRAppearance {
        baseColor 1 0 0
        roughness 1
        metalness 0
      }
      geometry Box {
        size 0.03 0.51 0.0005
      }
    }
  ]
  name "solid(6)"
  locked TRUE
}
Solid {
  children [
    Shape {
      appearance PBRAppearance {
        baseColor 0 0 0
        roughness 1
        metalness 0
      }
      geometry Mesh {
        url [
          "../path/outer_path.obj"
        ]
      }
    }
  ]
  name "solid(2)"
  boundingObject Mesh {
    url [
      "../path/outer_path.obj"
    ]
  }
  locked TRUE
}
Solid {
  children [
    Shape {
      appearance PBRAppearance {
        baseColor 0 0 0
        roughness 1
        metalness 0
      }
      geometry Mesh {
        url [
          "../path/inner_path.obj"
        ]
      }
    }
  ]
  name "solid(7)"
  boundingObject Mesh {
    url [
      "../path/inner_path.obj"
    ]
  }
  locked TRUE
}
Robot {
  translation -0.4857756557870738 -0.5958360575687202 0.02881048757944874
  rotation 0.03887942199342155 0.0758680943746671 0.9963595850903497 -0.9501439508028762
  children [
    DEF cam Solid {
      translation 0.049 0 0.019
      rotation 0 1 0 5.307156870259904e-06
      children [
        DEF camera Camera {
          fieldOfView 1.2
          width 640
          height 640
        }
        Shape {
          appearance PBRAppearance {
            baseColor 1 0 0
            roughness 1
            metalness 0
          }
          geometry Cylinder {
            height 0.005
            radius 0.005
          }
        }
      ]
      name "solid(1)"
    }
    Pose {
      children [
        DEF Body Shape {
          appearance PBRAppearance {
            baseColor 0 0.3 1
            roughness 1
            metalness 0
          }
          geometry Cylinder {
            height 0.05
            radius 0.05
          }
        }
      ]
    }
    HingeJoint {
      jointParameters HingeJointParameters {
        position 96.91882652600042
        axis 0 1 0
        anchor 0 0.05 -0.01
      }
      device [
        RotationalMotor {
          name "motor_1"
        }
      ]
      endPoint Solid {
        translation 0 0.05 -0.01
        rotation -0.16711868122700654 -0.6971614136335298 0.6971637610529139 3.4727684449610288
        children [
          DEF Wheel Shape {
            appearance PBRAppearance {
              baseColor 0 0 0
              roughness 1
              metalness 0
            }
            geometry Cylinder {
              height 0.005
              radius 0.019
            }
          }
        ]
        boundingObject USE Wheel
        physics Physics {
        }
        linearVelocity 0.011303258470138702 -0.015818344706692827 -1.2457430549199322e-09
        angularVelocity 0.8135068793212953 0.5815621624645626 0.18164204730742511
      }
    }
    HingeJoint {
      jointParameters HingeJointParameters {
        position 193.78800016757472
        axis 0 1 0
        anchor 0 -0.05 -0.01
      }
      device [
        RotationalMotor {
          name "motor_2"
        }
      ]
      endPoint Solid {
        translation 0 -0.05 -0.01
        rotation -0.7945860571770379 0.4293202513939948 -0.42932169696259964 4.484451430218295
        children [
          DEF Wheel Shape {
            appearance PBRAppearance {
              baseColor 0 0 0
              roughness 1
              metalness 0
            }
            geometry Cylinder {
              height 0.005
              radius 0.019
            }
          }
        ]
        boundingObject USE Wheel
        physics Physics {
        }
        linearVelocity 0.021841750661115166 -0.03055890366244142 1.5168552980529831e-09
        angularVelocity 1.6272418583977502 1.1628032522202127 0.1828746440252542
      }
    }
  ]
  boundingObject USE Body
  physics Physics {
  }
  controller "main"
  linearVelocity 0.01645764000619066 -0.02327075535775524 1.27637368101051e-10
  angularVelocity -2.7349088906379782e-08 1.507379788677959e-08 0.18118794423151827
}
